<?xml version="1.0" ?>
<!-- Generated using onshape-to-robot -->
<!-- Onshape https://cad.onshape.com/documents/edea034631796554fe7de906/w/0725cd49d9878c86b643a14d/e/ef4419f73ceb4e549626bf9b -->
<robot name="C:\Users\David\desktop\v1_urdf">
  <!-- Link torso -->
  <link name="torso">
    <inertial>
      <origin xyz="-2.59269e-07 0.0654878 -0.0078332" rpy="0 0 0"/>
      <mass value="1.25968"/>
      <inertia ixx="0.00401254" ixy="-3.98569e-09" ixz="-1.83499e-08" iyy="0.00450993" iyz="0.000396725" izz="0.00269862"/>
    </inertial>
    <!-- Part torso_parts -->
    <visual>
      <origin xyz="-2.59269e-07 0.0654878 -0.0078332" rpy="0 -0 0"/>
      <geometry>
        <mesh filename="package://assets\merged\torso_visual.stl"/>
      </geometry>
      <material name="torso_parts_material">
        <color rgba="0.505757 0.672338 0.668928 1.0"/>
      </material>
    </visual>
    <collision>
      <origin xyz="-2.59269e-07 0.0654878 -0.0078332" rpy="0 -0 0"/>
      <geometry>
        <mesh filename="package://assets\merged\torso_collision.stl"/>
      </geometry>
    </collision>
  </link>
  <!-- Link yaw_adapter -->
  <link name="yaw_adapter">
    <inertial>
      <origin xyz="3.24372e-11 -0.000458903 -0.0137673" rpy="0 0 0"/>
      <mass value="0.015882"/>
      <inertia ixx="6.07525e-06" ixy="1.97385e-13" ixz="-1.22003e-14" iyy="2.82322e-06" iyz="-1.23672e-07" izz="4.89494e-06"/>
    </inertial>
    <!-- Part yaw_adapter_parts -->
    <visual>
      <origin xyz="3.24372e-11 -0.000458903 -0.0137673" rpy="-1.34106e-29 2.59679e-29 3.14159"/>
      <geometry>
        <mesh filename="package://assets\merged\yaw_adapter_visual.stl"/>
      </geometry>
      <material name="yaw_adapter_parts_material">
        <color rgba="0.0862745 0.317647 0.690196 1.0"/>
      </material>
    </visual>
    <collision>
      <origin xyz="3.24372e-11 -0.000458903 -0.0137673" rpy="-1.34106e-29 2.59679e-29 3.14159"/>
      <geometry>
        <mesh filename="package://assets\merged\yaw_adapter_collision.stl"/>
      </geometry>
    </collision>
  </link>
  <!-- Link pitch_roll_housing -->
  <link name="pitch_roll_housing">
    <inertial>
      <origin xyz="-0.000322808 -0.0137311 0.00416399" rpy="0 0 0"/>
      <mass value="0.152157"/>
      <inertia ixx="0.000116157" ixy="2.64631e-07" ixz="7.24198e-07" iyy="9.723e-05" iyz="-5.97209e-06" izz="5.17002e-05"/>
    </inertial>
    <!-- Part pitch_roll_housing_parts -->
    <visual>
      <origin xyz="-0.000322808 -0.0137311 0.00416399" rpy="-1.5708 -2.2803e-29 -2.59679e-29"/>
      <geometry>
        <mesh filename="package://assets\merged\pitch_roll_housing_visual.stl"/>
      </geometry>
      <material name="pitch_roll_housing_parts_material">
        <color rgba="0.391406 0.460207 0.389068 1.0"/>
      </material>
    </visual>
    <collision>
      <origin xyz="-0.000322808 -0.0137311 0.00416399" rpy="-1.5708 -2.2803e-29 -2.59679e-29"/>
      <geometry>
        <mesh filename="package://assets\merged\pitch_roll_housing_collision.stl"/>
      </geometry>
    </collision>
  </link>
  <!-- Link knee_housing -->
  <link name="knee_housing">
    <inertial>
      <origin xyz="1.09705e-06 -0.0701498 0.0183268" rpy="0 0 0"/>
      <mass value="0.0990093"/>
      <inertia ixx="0.000110748" ixy="8.55711e-09" ixz="1.84109e-09" iyy="3.19926e-05" iyz="-2.68941e-06" izz="9.22632e-05"/>
    </inertial>
    <!-- Part knee_housing_parts -->
    <visual>
      <origin xyz="1.09705e-06 -0.0701498 0.0183268" rpy="-1.5708 -1.5708 0"/>
      <geometry>
        <mesh filename="package://assets\merged\knee_housing_visual.stl"/>
      </geometry>
      <material name="knee_housing_parts_material">
        <color rgba="0.347706 0.466239 0.293669 1.0"/>
      </material>
    </visual>
    <collision>
      <origin xyz="1.09705e-06 -0.0701498 0.0183268" rpy="-1.5708 -1.5708 0"/>
      <geometry>
        <mesh filename="package://assets\merged\knee_housing_collision.stl"/>
      </geometry>
    </collision>
  </link>
  <!-- Link knee_ankle_rotor_case -->
  <link name="knee_ankle_rotor_case">
    <inertial>
      <origin xyz="1.04083e-17 -0.0420709 0.0188591" rpy="0 0 0"/>
      <mass value="0.043594"/>
      <inertia ixx="5.21675e-05" ixy="0" ixz="0" iyy="1.91573e-05" iyz="8.24107e-09" izz="3.72586e-05"/>
    </inertial>
    <!-- Part knee_ankle_rotor_case_parts -->
    <visual>
      <origin xyz="1.38778e-17 -0.0420709 0.0188591" rpy="-1.5708 -1.5708 0"/>
      <geometry>
        <mesh filename="package://assets\merged\knee_ankle_rotor_case_visual.stl"/>
      </geometry>
      <material name="knee_ankle_rotor_case_parts_material">
        <color rgba="0.231373 0.380392 0.705882 1.0"/>
      </material>
    </visual>
    <collision>
      <origin xyz="1.38778e-17 -0.0420709 0.0188591" rpy="-1.5708 -1.5708 0"/>
      <geometry>
        <mesh filename="package://assets\merged\knee_ankle_rotor_case_collision.stl"/>
      </geometry>
    </collision>
  </link>
  <!-- Link sts3250 -->
  <link name="sts3250">
    <inertial>
      <origin xyz="0.0154245 -0.0123715 -0.0184091" rpy="0 0 0"/>
      <mass value="0.14555"/>
      <inertia ixx="4.62339e-05" ixy="2.1482e-06" ixz="9.51397e-07" iyy="0.000103932" iyz="-5.93605e-08" izz="0.00011985"/>
    </inertial>
    <!-- Part sts3250_parts -->
    <visual>
      <origin xyz="0.0154245 -0.0123715 -0.0184091" rpy="1.5708 1.5708 0"/>
      <geometry>
        <mesh filename="package://assets\merged\sts3250_visual.stl"/>
      </geometry>
      <material name="sts3250_parts_material">
        <color rgba="0.396357 0.456175 0.399432 1.0"/>
      </material>
    </visual>
    <collision>
      <origin xyz="0.0154245 -0.0123715 -0.0184091" rpy="1.5708 1.5708 0"/>
      <geometry>
        <mesh filename="package://assets\merged\sts3250_collision.stl"/>
      </geometry>
    </collision>
  </link>
  <!-- Link foot -->
  <link name="foot">
    <inertial>
      <origin xyz="5.58176e-09 0.0197347 -0.0475044" rpy="0 0 0"/>
      <mass value="0.0879022"/>
      <inertia ixx="0.000142062" ixy="-8.38229e-13" ixz="-7.8354e-12" iyy="0.000157128" iyz="-6.00865e-06" izz="2.44044e-05"/>
    </inertial>
    <!-- Part foot_parts -->
    <visual>
      <origin xyz="5.58176e-09 0.0197347 -0.0475044" rpy="1.5708 2.32206e-80 2.06626e-48"/>
      <geometry>
        <mesh filename="package://assets\merged\foot_visual.stl"/>
      </geometry>
      <material name="foot_parts_material">
        <color rgba="0.65098 0.486275 0.0196078 1.0"/>
      </material>
    </visual>
    <collision>
      <origin xyz="5.58176e-09 0.0197347 -0.0475044" rpy="1.5708 2.32206e-80 2.06626e-48"/>
      <geometry>
        <mesh filename="package://assets\merged\foot_collision.stl"/>
      </geometry>
    </collision>
  </link>
  <!-- Link foot_sole -->
  <link name="foot_sole">
    <inertial>
      <origin xyz="0.0 0.0 0.0" rpy="0.0 0.0 0.0"/>
      <mass value="0.01" />
      <inertia ixx="0.0001" ixy="0"  ixz="0" iyy="0.0001" iyz="0"  izz="0.0001" />
    </inertial>
  </link>
  <!-- Joint from foot_sole to foot -->
  <joint name="right_sole_joint_fixed" type="fixed">
    <origin xyz="0 0.03 0.0275" rpy="1.57079632679 1.57079632679 0" />
    <axis xyz="1 0 0"/>
    <dynamics damping="0.0" friction="0.0"/>
    <parent link="foot" />
    <child link="foot_sole" />
  </joint>
  <!-- Joint from sts3250 to foot -->
  <joint name="right_ankle_roll" type="revolute">
    <origin xyz="0.024725 9.04235e-10 -0.018825" rpy="6.12323e-17 1.5708 0"/>
    <parent link="sts3250"/>
    <child link="foot"/>
    <axis xyz="0 0 1"/>
    <limit effort="10" velocity="10" lower="-3.141592653589793" upper="3.141592653589793"/>
  </joint>
  <!-- Joint from knee_ankle_rotor_case to sts3250 -->
  <joint name="right_ankle_pitch" type="revolute">
    <origin xyz="1.38778e-17 -0.09522 2.77556e-17" rpy="3.14159 6.12323e-17 -1.49976e-32"/>
    <parent link="knee_ankle_rotor_case"/>
    <child link="sts3250"/>
    <axis xyz="0 0 1"/>
    <limit effort="10" velocity="10" lower="-3.141592653589793" upper="3.141592653589793"/>
  </joint>
  <!-- Joint from knee_housing to knee_ankle_rotor_case -->
  <joint name="right_knee" type="revolute">
    <origin xyz="0 -0.10022 0" rpy="0 -0 0"/>
    <parent link="knee_housing"/>
    <child link="knee_ankle_rotor_case"/>
    <axis xyz="0 0 1"/>
    <limit effort="10" velocity="10" lower="-3.141592653589793" upper="3.141592653589793"/>
  </joint>
  <!-- Joint from pitch_roll_housing to knee_housing -->
  <joint name="right_hip_pitch" type="revolute">
    <origin xyz="-0.018825 -1.11022e-16 0.018825" rpy="6.12323e-17 1.5708 0"/>
    <parent link="pitch_roll_housing"/>
    <child link="knee_housing"/>
    <axis xyz="0 0 1"/>
    <limit effort="10" velocity="10" lower="-3.141592653589793" upper="3.141592653589793"/>
  </joint>
  <!-- Joint from yaw_adapter to pitch_roll_housing -->
  <joint name="right_hip_roll" type="revolute">
    <origin xyz="-6.93889e-18 -0.021075 -0.03011" rpy="1.5708 -0 3.14159"/>
    <parent link="yaw_adapter"/>
    <child link="pitch_roll_housing"/>
    <axis xyz="0 0 1"/>
    <limit effort="10" velocity="10" lower="-3.141592653589793" upper="3.141592653589793"/>
  </joint>
  <!-- Joint from torso to yaw_adapter -->
  <joint name="right_hip_yaw" type="revolute">
    <origin xyz="-0.04236 0.04511 -0.0794175" rpy="-1.34106e-29 2.59679e-29 -3.14159"/>
    <parent link="torso"/>
    <child link="yaw_adapter"/>
    <axis xyz="0 0 1"/>
    <limit effort="10" velocity="10" lower="-3.141592653589793" upper="3.141592653589793"/>
  </joint>
  <!-- Link yaw_adapter_2 -->
  <link name="yaw_adapter_2">
    <inertial>
      <origin xyz="3.24372e-11 -0.000458903 -0.0137673" rpy="0 0 0"/>
      <mass value="0.015882"/>
      <inertia ixx="6.07525e-06" ixy="1.97385e-13" ixz="-1.22003e-14" iyy="2.82322e-06" iyz="-1.23672e-07" izz="4.89494e-06"/>
    </inertial>
    <!-- Part yaw_adapter_2_parts -->
    <visual>
      <origin xyz="3.24372e-11 -0.000458903 -0.0137673" rpy="-1.33983e-29 -1.22465e-16 3.14159"/>
      <geometry>
        <mesh filename="package://assets\merged\yaw_adapter_2_visual.stl"/>
      </geometry>
      <material name="yaw_adapter_2_parts_material">
        <color rgba="0.0862745 0.317647 0.690196 1.0"/>
      </material>
    </visual>
    <collision>
      <origin xyz="3.24372e-11 -0.000458903 -0.0137673" rpy="-1.33983e-29 -1.22465e-16 3.14159"/>
      <geometry>
        <mesh filename="package://assets\merged\yaw_adapter_2_collision.stl"/>
      </geometry>
    </collision>
  </link>
  <!-- Link bearing -->
  <link name="bearing">
    <inertial>
      <origin xyz="-0.000322808 -0.0137311 0.00416399" rpy="0 0 0"/>
      <mass value="0.152157"/>
      <inertia ixx="0.000116157" ixy="2.64631e-07" ixz="7.24198e-07" iyy="9.723e-05" iyz="-5.97209e-06" izz="5.17002e-05"/>
    </inertial>
    <!-- Part bearing_parts -->
    <visual>
      <origin xyz="-0.000322808 -0.0137311 0.00416399" rpy="-1.5708 -1.14008e-28 1.22465e-16"/>
      <geometry>
        <mesh filename="package://assets\merged\bearing_visual.stl"/>
      </geometry>
      <material name="bearing_parts_material">
        <color rgba="0.391406 0.460207 0.389068 1.0"/>
      </material>
    </visual>
    <collision>
      <origin xyz="-0.000322808 -0.0137311 0.00416399" rpy="-1.5708 -1.14008e-28 1.22465e-16"/>
      <geometry>
        <mesh filename="package://assets\merged\bearing_collision.stl"/>
      </geometry>
    </collision>
  </link>
  <!-- Link sts3250_2 -->
  <link name="sts3250_2">
    <inertial>
      <origin xyz="1.09705e-06 0.0701498 0.0193232" rpy="0 0 0"/>
      <mass value="0.0990093"/>
      <inertia ixx="0.000110748" ixy="-8.55711e-09" ixz="-1.84109e-09" iyy="3.19926e-05" iyz="-2.68941e-06" izz="9.22632e-05"/>
    </inertial>
    <!-- Part sts3250_2_parts -->
    <visual>
      <origin xyz="1.09705e-06 0.0701498 0.0193232" rpy="1.5708 1.5708 0"/>
      <geometry>
        <mesh filename="package://assets\merged\sts3250_2_visual.stl"/>
      </geometry>
      <material name="sts3250_2_parts_material">
        <color rgba="0.347706 0.466239 0.293669 1.0"/>
      </material>
    </visual>
    <collision>
      <origin xyz="1.09705e-06 0.0701498 0.0193232" rpy="1.5708 1.5708 0"/>
      <geometry>
        <mesh filename="package://assets\merged\sts3250_2_collision.stl"/>
      </geometry>
    </collision>
  </link>
  <!-- Link knee_ankle_rotor_case_2 -->
  <link name="knee_ankle_rotor_case_2">
    <inertial>
      <origin xyz="1.04083e-17 0.0420709 0.0187909" rpy="0 0 0"/>
      <mass value="0.043594"/>
      <inertia ixx="5.21675e-05" ixy="0" ixz="0" iyy="1.91573e-05" iyz="8.24107e-09" izz="3.72586e-05"/>
    </inertial>
    <!-- Part knee_ankle_rotor_case_2_parts -->
    <visual>
      <origin xyz="1.38778e-17 0.0420709 0.0187909" rpy="1.5708 1.5708 0"/>
      <geometry>
        <mesh filename="package://assets\merged\knee_ankle_rotor_case_2_visual.stl"/>
      </geometry>
      <material name="knee_ankle_rotor_case_2_parts_material">
        <color rgba="0.231373 0.380392 0.705882 1.0"/>
      </material>
    </visual>
    <collision>
      <origin xyz="1.38778e-17 0.0420709 0.0187909" rpy="1.5708 1.5708 0"/>
      <geometry>
        <mesh filename="package://assets\merged\knee_ankle_rotor_case_2_collision.stl"/>
      </geometry>
    </collision>
  </link>
  <!-- Link sts3250_3 -->
  <link name="sts3250_3">
    <inertial>
      <origin xyz="0.0154245 0.0123715 -0.0192409" rpy="0 0 0"/>
      <mass value="0.14555"/>
      <inertia ixx="4.62339e-05" ixy="-2.1482e-06" ixz="-9.51397e-07" iyy="0.000103932" iyz="-5.93605e-08" izz="0.00011985"/>
    </inertial>
    <!-- Part sts3250_3_parts -->
    <visual>
      <origin xyz="0.0154245 0.0123715 -0.0192409" rpy="-1.5708 -1.5708 0"/>
      <geometry>
        <mesh filename="package://assets\merged\sts3250_3_visual.stl"/>
      </geometry>
      <material name="sts3250_3_parts_material">
        <color rgba="0.396357 0.456175 0.399432 1.0"/>
      </material>
    </visual>
    <collision>
      <origin xyz="0.0154245 0.0123715 -0.0192409" rpy="-1.5708 -1.5708 0"/>
      <geometry>
        <mesh filename="package://assets\merged\sts3250_3_collision.stl"/>
      </geometry>
    </collision>
  </link>
  <!-- Link foot_2 -->
  <link name="foot_2">
    <inertial>
      <origin xyz="5.58176e-09 0.0197347 -0.0475044" rpy="0 0 0"/>
      <mass value="0.0879022"/>
      <inertia ixx="0.000142062" ixy="-8.38229e-13" ixz="-7.8354e-12" iyy="0.000157128" iyz="-6.00865e-06" izz="2.44044e-05"/>
    </inertial>
    <!-- Part foot_2_parts -->
    <visual>
      <origin xyz="5.58176e-09 0.0197347 -0.0475044" rpy="1.5708 4.64413e-80 4.13252e-48"/>
      <geometry>
        <mesh filename="package://assets\merged\foot_2_visual.stl"/>
      </geometry>
      <material name="foot_2_parts_material">
        <color rgba="0.65098 0.486275 0.0196078 1.0"/>
      </material>
    </visual>
    <collision>
      <origin xyz="5.58176e-09 0.0197347 -0.0475044" rpy="1.5708 4.64413e-80 4.13252e-48"/>
      <geometry>
        <mesh filename="package://assets\merged\foot_2_collision.stl"/>
      </geometry>
    </collision>
  </link>
  <!-- Link foot_2_sole -->
  <link name="foot_2_sole">
    <inertial>
      <origin xyz="0.0 0.0 0.0" rpy="0.0 0.0 0.0"/>
      <mass value="0.01" />
      <inertia ixx="0.0001" ixy="0"  ixz="0" iyy="0.0001" iyz="0"  izz="0.0001" />
    </inertial>
  </link>
  <!-- Joint from foot_2_sole to foot_2 -->
  <joint name="left_sole_joint_fixed" type="fixed">
    <origin xyz="0 0.03 0.0275" rpy="1.57079632679 -1.57079632679 0" />
    <axis xyz="1 0 0"/>
    <dynamics damping="0.0" friction="0.0"/>
    <parent link="foot_2" />
    <child link="foot_2_sole" />
  </joint>
  <!-- Joint from sts3250_3 to foot_2 -->
  <joint name="left_ankle_roll" type="revolute">
    <origin xyz="0.024725 -9.04235e-10 -0.018825" rpy="-3.14159 -1.5708 0"/>
    <parent link="sts3250_3"/>
    <child link="foot_2"/>
    <axis xyz="0 0 1"/>
    <limit effort="10" velocity="10" lower="-3.141592653589793" upper="3.141592653589793"/>
  </joint>
  <!-- Joint from knee_ankle_rotor_case_2 to sts3250_3 -->
  <joint name="left_ankle_pitch" type="revolute">
    <origin xyz="1.38778e-17 0.09522 0" rpy="3.14159 -6.12323e-17 1.49976e-32"/>
    <parent link="knee_ankle_rotor_case_2"/>
    <child link="sts3250_3"/>
    <axis xyz="0 0 1"/>
    <limit effort="10" velocity="10" lower="-3.141592653589793" upper="3.141592653589793"/>
  </joint>
  <!-- Joint from sts3250_2 to knee_ankle_rotor_case_2 -->
  <joint name="left_knee" type="revolute">
    <origin xyz="0 0.10022 0" rpy="0 -0 0"/>
    <parent link="sts3250_2"/>
    <child link="knee_ankle_rotor_case_2"/>
    <axis xyz="0 0 1"/>
    <limit effort="10" velocity="10" lower="-3.141592653589793" upper="3.141592653589793"/>
  </joint>
  <!-- Joint from bearing to sts3250_2 -->
  <joint name="left_hip_pitch" type="revolute">
    <origin xyz="0.018825 -1.11022e-16 0.018825" rpy="3.14159 1.5708 0"/>
    <parent link="bearing"/>
    <child link="sts3250_2"/>
    <axis xyz="0 0 1"/>
    <limit effort="10" velocity="10" lower="-3.141592653589793" upper="3.141592653589793"/>
  </joint>
  <!-- Joint from yaw_adapter_2 to bearing -->
  <joint name="left_hip_roll" type="revolute">
    <origin xyz="6.93889e-18 -0.021075 -0.03011" rpy="1.5708 -1.03834e-28 -3.14159"/>
    <parent link="yaw_adapter_2"/>
    <child link="bearing"/>
    <axis xyz="0 0 1"/>
    <limit effort="10" velocity="10" lower="-3.141592653589793" upper="3.141592653589793"/>
  </joint>
  <!-- Joint from torso to yaw_adapter_2 -->
  <joint name="left_hip_yaw" type="revolute">
    <origin xyz="0.04236 0.04511 -0.0794175" rpy="-1.33983e-29 -1.22465e-16 -3.14159"/>
    <parent link="torso"/>
    <child link="yaw_adapter_2"/>
    <axis xyz="0 0 1"/>
    <limit effort="10" velocity="10" lower="-3.141592653589793" upper="3.141592653589793"/>
  </joint>
  <!-- Link shoulder_rightangle -->
  <link name="shoulder_rightangle">
    <inertial>
      <origin xyz="-0.000405734 0.00767679 -0.0212962" rpy="0 0 0"/>
      <mass value="0.0317299"/>
      <inertia ixx="1.35964e-05" ixy="3.98666e-07" ixz="-2.2438e-07" iyy="1.71141e-05" iyz="4.24225e-06" izz="1.77104e-05"/>
    </inertial>
    <!-- Part shoulder_rightangle_parts -->
    <visual>
      <origin xyz="-0.000405734 0.00767679 -0.0212962" rpy="1.5708 1.5708 0"/>
      <geometry>
        <mesh filename="package://assets\merged\shoulder_rightangle_visual.stl"/>
      </geometry>
      <material name="shoulder_rightangle_parts_material">
        <color rgba="0.647059 0.647059 0.647059 1.0"/>
      </material>
    </visual>
    <collision>
      <origin xyz="-0.000405734 0.00767679 -0.0212962" rpy="1.5708 1.5708 0"/>
      <geometry>
        <mesh filename="package://assets\merged\shoulder_rightangle_collision.stl"/>
      </geometry>
    </collision>
  </link>
  <!-- Link bicep -->
  <link name="bicep">
    <inertial>
      <origin xyz="-0.000137418 -0.0333694 -0.0209277" rpy="0 0 0"/>
      <mass value="0.0928907"/>
      <inertia ixx="0.000123449" ixy="-8.13477e-07" ixz="1.02394e-07" iyy="2.42426e-05" iyz="-1.32317e-05" izz="0.00011859"/>
    </inertial>
    <!-- Part bicep_parts -->
    <visual>
      <origin xyz="-0.000137418 -0.0333694 -0.0209277" rpy="-1.5708 6.12323e-17 2.47818e-16"/>
      <geometry>
        <mesh filename="package://assets\merged\bicep_visual.stl"/>
      </geometry>
      <material name="bicep_parts_material">
        <color rgba="0.457862 0.518983 0.499247 1.0"/>
      </material>
    </visual>
    <collision>
      <origin xyz="-0.000137418 -0.0333694 -0.0209277" rpy="-1.5708 6.12323e-17 2.47818e-16"/>
      <geometry>
        <mesh filename="package://assets\merged\bicep_collision.stl"/>
      </geometry>
    </collision>
  </link>
  <!-- Link forearm -->
  <link name="forearm">
    <inertial>
      <origin xyz="0.0026095 -0.0296011 -0.0182997" rpy="0 0 0"/>
      <mass value="0.0855891"/>
      <inertia ixx="0.000110205" ixy="1.24531e-05" ixz="2.54898e-07" iyy="1.9857e-05" iyz="-1.88097e-06" izz="0.0001067"/>
    </inertial>
    <!-- Part forearm_parts -->
    <visual>
      <origin xyz="0.0026095 -0.0296011 -0.0182997" rpy="-1.5708 -1.5708 0"/>
      <geometry>
        <mesh filename="package://assets\merged\forearm_visual.stl"/>
      </geometry>
      <material name="forearm_parts_material">
        <color rgba="0.439862 0.517822 0.503377 1.0"/>
      </material>
    </visual>
    <collision>
      <origin xyz="0.0026095 -0.0296011 -0.0182997" rpy="-1.5708 -1.5708 0"/>
      <geometry>
        <mesh filename="package://assets\merged\forearm_collision.stl"/>
      </geometry>
    </collision>
  </link>
  <!-- Joint from bicep to forearm -->
  <joint name="left_elbow" type="revolute">
    <origin xyz="0.019825 -0.09586 -0.01345" rpy="-4.95635e-16 1.5708 0"/>
    <parent link="bicep"/>
    <child link="forearm"/>
    <axis xyz="0 0 1"/>
    <limit effort="10" velocity="10" lower="-3.141592653589793" upper="3.141592653589793"/>
  </joint>
  <!-- Joint from shoulder_rightangle to bicep -->
  <joint name="left_shoulder_roll" type="revolute">
    <origin xyz="-0.017825 0.038 -0.0387252" rpy="3.14159 1.5708 0"/>
    <parent link="shoulder_rightangle"/>
    <child link="bicep"/>
    <axis xyz="0 0 1"/>
    <limit effort="10" velocity="10" lower="-3.141592653589793" upper="3.141592653589793"/>
  </joint>
  <!-- Joint from torso to shoulder_rightangle -->
  <joint name="left_shoulder_pitch" type="revolute">
    <origin xyz="0.061185 0.02011 0.0605925" rpy="-1.5708 6.88754e-49 1.5708"/>
    <parent link="torso"/>
    <child link="shoulder_rightangle"/>
    <axis xyz="0 0 1"/>
    <limit effort="10" velocity="10" lower="-3.141592653589793" upper="3.141592653589793"/>
  </joint>
  <!-- Link shoulder_rightangle_2 -->
  <link name="shoulder_rightangle_2">
    <inertial>
      <origin xyz="0.000405734 -0.00767679 -0.0212962" rpy="0 0 0"/>
      <mass value="0.0317299"/>
      <inertia ixx="1.35964e-05" ixy="3.98666e-07" ixz="2.2438e-07" iyy="1.71141e-05" iyz="-4.24225e-06" izz="1.77104e-05"/>
    </inertial>
    <!-- Part shoulder_rightangle_2_parts -->
    <visual>
      <origin xyz="0.000405734 -0.00767679 -0.0212962" rpy="-1.5708 -1.5708 0"/>
      <geometry>
        <mesh filename="package://assets\merged\shoulder_rightangle_2_visual.stl"/>
      </geometry>
      <material name="shoulder_rightangle_2_parts_material">
        <color rgba="0.647059 0.647059 0.647059 1.0"/>
      </material>
    </visual>
    <collision>
      <origin xyz="0.000405734 -0.00767679 -0.0212962" rpy="-1.5708 -1.5708 0"/>
      <geometry>
        <mesh filename="package://assets\merged\shoulder_rightangle_2_collision.stl"/>
      </geometry>
    </collision>
  </link>
  <!-- Link sts3250_4 -->
  <link name="sts3250_4">
    <inertial>
      <origin xyz="-0.000139766 0.0333694 -0.0209277" rpy="0 0 0"/>
      <mass value="0.0928907"/>
      <inertia ixx="0.000123449" ixy="7.95519e-07" ixz="1.06717e-07" iyy="2.42425e-05" iyz="1.32317e-05" izz="0.00011859"/>
    </inertial>
    <!-- Part sts3250_4_parts -->
    <visual>
      <origin xyz="-0.000139766 0.0333694 -0.0209277" rpy="-1.5708 -6.12323e-17 3.14159"/>
      <geometry>
        <mesh filename="package://assets\merged\sts3250_4_visual.stl"/>
      </geometry>
      <material name="sts3250_4_parts_material">
        <color rgba="0.457862 0.518983 0.499247 1.0"/>
      </material>
    </visual>
    <collision>
      <origin xyz="-0.000139766 0.0333694 -0.0209277" rpy="-1.5708 -6.12323e-17 3.14159"/>
      <geometry>
        <mesh filename="package://assets\merged\sts3250_4_collision.stl"/>
      </geometry>
    </collision>
  </link>
  <!-- Link sts3250_5 -->
  <link name="sts3250_5">
    <inertial>
      <origin xyz="-0.00260696 -0.0296011 -0.0182997" rpy="0 0 0"/>
      <mass value="0.0855891"/>
      <inertia ixx="0.000110205" ixy="-1.24702e-05" ixz="-2.58671e-07" iyy="1.98582e-05" iyz="-1.88118e-06" izz="0.000106701"/>
    </inertial>
    <!-- Part sts3250_5_parts -->
    <visual>
      <origin xyz="-0.00260696 -0.0296011 -0.0182997" rpy="-1.5708 1.5708 0"/>
      <geometry>
        <mesh filename="package://assets\merged\sts3250_5_visual.stl"/>
      </geometry>
      <material name="sts3250_5_parts_material">
        <color rgba="0.439862 0.517822 0.503377 1.0"/>
      </material>
    </visual>
    <collision>
      <origin xyz="-0.00260696 -0.0296011 -0.0182997" rpy="-1.5708 1.5708 0"/>
      <geometry>
        <mesh filename="package://assets\merged\sts3250_5_collision.stl"/>
      </geometry>
    </collision>
  </link>
  <!-- Joint from sts3250_4 to sts3250_5 -->
  <joint name="right_elbow" type="revolute">
    <origin xyz="0.019825 0.09586 -0.01345" rpy="-3.14159 -1.5708 0"/>
    <parent link="sts3250_4"/>
    <child link="sts3250_5"/>
    <axis xyz="0 0 1"/>
    <limit effort="10" velocity="10" lower="-3.141592653589793" upper="3.141592653589793"/>
  </joint>
  <!-- Joint from shoulder_rightangle_2 to sts3250_4 -->
  <joint name="right_shoulder_roll" type="revolute">
    <origin xyz="-0.019825 -0.038 -0.0387252" rpy="3.14159 1.5708 0"/>
    <parent link="shoulder_rightangle_2"/>
    <child link="sts3250_4"/>
    <axis xyz="0 0 1"/>
    <limit effort="10" velocity="10" lower="-3.141592653589793" upper="3.141592653589793"/>
  </joint>
  <!-- Joint from torso to shoulder_rightangle_2 -->
  <joint name="right_shoulder_pitch" type="revolute">
    <origin xyz="-0.061185 0.02011 0.0605925" rpy="1.5708 -6.88754e-49 1.5708"/>
    <parent link="torso"/>
    <child link="shoulder_rightangle_2"/>
    <axis xyz="0 0 1"/>
    <limit effort="10" velocity="10" lower="-3.141592653589793" upper="3.141592653589793"/>
  </joint>
  <!-- Link sts3250_6 -->
  <link name="sts3250_6">
    <inertial>
      <origin xyz="0.00146817 -0.00929036 -0.0151995" rpy="0 0 0"/>
      <mass value="0.0622194"/>
      <inertia ixx="1.83354e-05" ixy="-1.1613e-07" ixz="1.3449e-07" iyy="1.41601e-05" iyz="8.44616e-07" izz="2.29833e-05"/>
    </inertial>
    <!-- Part sts3250_6_parts -->
    <visual>
      <origin xyz="0.00146817 -0.00929036 -0.0151995" rpy="3.14159 9.17574e-66 3.74628e-50"/>
      <geometry>
        <mesh filename="package://assets\merged\sts3250_6_visual.stl"/>
      </geometry>
      <material name="sts3250_6_parts_material">
        <color rgba="0.386349 0.417291 0.372244 1.0"/>
      </material>
    </visual>
    <collision>
      <origin xyz="0.00146817 -0.00929036 -0.0151995" rpy="3.14159 9.17574e-66 3.74628e-50"/>
      <geometry>
        <mesh filename="package://assets\merged\sts3250_6_collision.stl"/>
      </geometry>
    </collision>
  </link>
  <!-- Link camera_enclosure -->
  <link name="camera_enclosure">
    <inertial>
      <origin xyz="0.0259913 -0.00211283 0.0195868" rpy="0 0 0"/>
      <mass value="0.0431312"/>
      <inertia ixx="3.21869e-05" ixy="4.09566e-07" ixz="2.56124e-07" iyy="3.45044e-05" iyz="-2.38572e-08" izz="7.90515e-06"/>
    </inertial>
    <!-- Part camera_enclosure_parts -->
    <visual>
      <origin xyz="0.0259913 -0.00211283 0.0195868" rpy="1.46897e-15 1.5708 0"/>
      <geometry>
        <mesh filename="package://assets\merged\camera_enclosure_visual.stl"/>
      </geometry>
      <material name="camera_enclosure_parts_material">
        <color rgba="0.623322 0.771679 0.860693 1.0"/>
      </material>
    </visual>
    <collision>
      <origin xyz="0.0259913 -0.00211283 0.0195868" rpy="1.46897e-15 1.5708 0"/>
      <geometry>
        <mesh filename="package://assets\merged\camera_enclosure_collision.stl"/>
      </geometry>
    </collision>
  </link>
  <!-- Joint from sts3250_6 to camera_enclosure -->
  <joint name="head_pitch" type="revolute">
    <origin xyz="0.0194521 0.00310933 -0.0166382" rpy="3.14159 1.5708 0"/>
    <parent link="sts3250_6"/>
    <child link="camera_enclosure"/>
    <axis xyz="0 0 1"/>
    <limit effort="10" velocity="10" lower="-3.141592653589793" upper="3.141592653589793"/>
  </joint>
  <!-- Joint from torso to sts3250_6 -->
  <joint name="head_yaw" type="revolute">
    <origin xyz="0 0.02011 0.0858825" rpy="-3.14159 -0 3.74628e-50"/>
    <parent link="torso"/>
    <child link="sts3250_6"/>
    <axis xyz="0 0 1"/>
    <limit effort="10" velocity="10" lower="-3.141592653589793" upper="3.141592653589793"/>
  </joint>
</robot>
